Workbook
Name Nom_0.405: 'LWN SHEET'!$AB$3:$AB$5
Name Nom_0.54: 'LWN SHEET'!$AC$3:$AC$5
Name Nom_0.675: 'LWN SHEET'!$AD$3:$AD$5
Name Nom_0.84: 'LWN SHEET'!$AE$3:$AE$8
Name Nom_1.05: 'LWN SHEET'!$AF$3:$AF$8
Name Nom_1.315: 'LWN SHEET'!$AG$3:$AG$8
Name Nom_1.5: 'LWN SHEET'!$AF$3:$AF$8
Name Nom_1.66: 'LWN SHEET'!$AH$3:$AH$8
Name Nom_1.9: 'LWN SHEET'!$AI$3:$AI$8
Name Nom_10.75: 'LWN SHEET'!$AR$3:$AR$13
Name Nom_12.75: 'LWN SHEET'!$AS$3:$AS$15
Name Nom_14: 'LWN SHEET'!$AT$3:$AT$14
Name Nom_16: 'LWN SHEET'!$AU$3:$AU$13
Name Nom_18: 'LWN SHEET'!$AV$3:$AV$15
Name Nom_2.375: 'LWN SHEET'!$AJ$3:$AJ$8
Name Nom_2.875: 'LWN SHEET'!$AK$3:$AK$8
Name Nom_20: 'LWN SHEET'!$AW$3:$AW$14
Name Nom_22: 'LWN SHEET'!$AX$3:$AX$12
Name Nom_24: 'LWN SHEET'!$AY$3:$AY$15
Name Nom_26: 'LWN SHEET'!$AZ$3:$AZ$5
Name Nom_28: 'LWN SHEET'!$BA$3:$BA$6
Name Nom_3.5: 'LWN SHEET'!$AL$3:$AL$8
Name Nom_30: 'LWN SHEET'!$BB$3:$BB$7
Name Nom_32: 'LWN SHEET'!$BC$3:$BC$8
Name Nom_34: 'LWN SHEET'!$BD$3:$BD$8
Name Nom_36: 'LWN SHEET'!$BE$3:$BE$8
Name Nom_4: 'LWN SHEET'!$AM$3:$AM$6
Name Nom_4.5: 'LWN SHEET'!$AN$3:$AN$9
Name Nom_42: 'LWN SHEET'!$BF$3:$BF$4
Name Nom_5.563: 'LWN SHEET'!$AO$3:$AO$9
Name Nom_6.625: 'LWN SHEET'!$AP$3:$AP$9
Name Nom_8.625: 'LWN SHEET'!$AQ$3:$AQ$14
Name ODs: 'LWN SHEET'!$AB$2:$BF$2

Sheet Rules
A1: UT SHEET INSTRUCTIONS
C2: Cells within the form that are highlighted yellow are the technician's responsibility to fill in. If reports are submitted with blank yellow cells will be marked as incomplete for technicians to fix. In instances where the procedure require less than 4 readings the UT Readings cell maybe left blank as long as it is in compliance with applicable procedures.
C6: Cells within the form that are highlighted red within the UT Reading cells as a result of an inspection are considered to either be outside of production tolerance. These readings shall be accompanied with a field verification and associated comment within the adjacent comment cell.
C10: If there is a previous reading, is outside of .020" target corrosion window. These readings shall be accompanied with a field verification and associated comment within the adjacent comment cell.
C14: Cells within the form that are highlighted blue within the UT Reading cells as a result of an inspection are considered to be in excess of a 25% growth limit. These readings shall be accompanied with a field verification and associated comment within the adjacent comment cell.
A18: The "Install Date" fields have been added to technician responsiblilities. For vessels you will use the manufacture date. If you only have the year of manufacturing use the date Jan. 1 of that year. For piping please talk with operations on an estimated start up date for the plant itself and once again if you only have a year utilize Jan. 1 of that year.
A21: The "NDE" fields have been added to the technician's responsibilities. Largely this will be left as "UT" desgination, but in some instances (largely small bore piping that is insulated) this fieldmay be designated as RT for CMLs that are being captured through radiographic methods.
A24: Long Weld Neck Nozzles
A25: OD Column | C25: Please provide the true OD for the nozzle in the OD column.
A29: Comments Column | C29: Please provide LWN indicating that it is a long weld neck, as well as the nominal pipe size, and flange rating.
A37: Example | C37: LWN 4" #300

Sheet Vessels
A1: Client: | C1: Location: | F1: Facility: | J1: Date: | N1: Vessels R.15
A2: Vessel Name: | F2: Description:
A3: P&ID Page | I3: Technician:
A4: Carbon or Stainless | G4: Seam:
A5: CML | B5: CML Location | C5: Component Type | D5: Component | E5: OD | F5: Nom. | G5: C.A. | H5: T-Min | I5: Mat. Spec. | J5: Seamed | K5: Pressure | L5: Temp. | M5: J.E. | N5: Access | O5: Insulation | P5: Install Date | Q5: Status | R5: NDE | S5: Previous Reading | T5: UT Reading | U5: Comments | V5: Long Weld Neck Nozzles
A6: 1.01 | Q6: Active | R6: UT | V6: OD Column | X6: Please provide the true OD for the nozzle in the OD column.
A7: 1.02 | Q7: Active | R7: UT
A8: 1.03 | Q8: Active | R8: UT
A9: 1.04 | Q9: Active | R9: UT
A10: 2.01 | Q10: Active | R10: UT | V10: Comments Column | X10: Please provide LWN indicating that it is a long weld neck, as well as the nominal pipe size, and flange rating.
A11: 2.02 | Q11: Active | R11: UT
A12: 2.03 | Q12: Active | R12: UT
A13: 2.04 | Q13: Active | R13: UT
A14: 3.01 | Q14: Active | R14: UT
A15: 3.02 | Q15: Active | R15: UT
A16: 3.03 | Q16: Active | R16: UT
A17: 3.04 | Q17: Active | R17: UT
A18: 4.01 | Q18: Active | R18: UT | V18: Example | X18: LWN 4" #300
A19: 4.02 | Q19: Active | R19: UT
A20: 4.03 | Q20: Active | R20: UT
A21: 4.04 | Q21: Active | R21: UT
A22: 5.01 | Q22: Active | R22: UT
A23: 5.02 | Q23: Active | R23: UT
A24: 5.03 | Q24: Active | R24: UT
A25: 5.04 | Q25: Active | R25: UT
A26: 6.01 | Q26: Active | R26: UT
A27: 6.02 | Q27: Active | R27: UT
A28: 6.03 | Q28: Active | R28: UT
A29: 6.04 | Q29: Active | R29: UT
A30: 7.01 | Q30: Active | R30: UT
... A1005: 250.4 | Q1005: Active | R1005: UT

Sheet Piping
A1: Client: | B1: KINETIC MIDSTREAM | C1: Location: | D1: ARTESIA NM | F1: Facility: | G1: KINGS LANDING | J1: Date: | K1: 46072 | N1: Piping R.15
A2: Pipe Circuit Name: | C2: Amine-034 | F2: Description: | I2: F-1202 To Open Drain
A3: P&ID Page | C3: K1GP-PID-1201 | I3: Technician: | J3: Carlos Santollo
A4: Carbon or Stainless | D4: Carbon | G4: Default
A5: CML | B5: CML Location | C5: Component Type | D5: Component | E5: OD | F5: Nom. | G5: C.A. | H5: T-Min | I5: Mat. Spec. | J5: Mat. Grade | K5: Pressure | L5: Temp. | M5: J.E. | N5: Access | O5: Insulation | P5: Install Date | Q5: Status | R5: NDE | S5: Prev. Reading | T5: UT Reading | U5: Comments | V5: NPS | W5: OD
A6: 1.01 | B6: North | C6: Piping | D6: Elbow | E6: 2.375 | F6: 0.218 | G6: 0 | I6: A234 | J6: WPB | K6: 150 | L6: 200 | M6: 1 | N6: Ground | O6: No | P6: 45658 | Q6: Active | R6: UT | T6: 0.266 | V6: 1/8" | W6: 0.405 | X6: =IF($G$4="Default", IF(ISNUMBER(SEARCH("Straight Pipe", D6)), "A106", IF(D6="", "", "A234")), "") -> A234 | Y6: =IF($G$4="Default", IF(ISNUMBER(SEARCH("Straight Pipe", D6)), "B", IF(D6="", "", "WPB")), "") -> WPB
A7: 1.02 | B7: Outside Radius | C7: Piping | D7: Elbow | E7: 2.375 | F7: 0.218 | G7: 0 | I7: A234 | J7: WPB | K7: 150 | L7: 200 | M7: 1 | N7: Ground | O7: No | P7: 45658 | Q7: Active | R7: UT | T7: 0.285 | V7: 1/4" | W7: 0.54 | X7: =IF($G$4="Default", IF(ISNUMBER(SEARCH("Straight Pipe", D7)), "A106", IF(D7="", "", "A234")), "") -> A234 | Y7: =IF($G$4="Default", IF(ISNUMBER(SEARCH("Straight Pipe", D7)), "B", IF(D7="", "", "WPB")), "") -> WPB
A8: 1.03 | B8: South | C8: Piping | D8: Elbow | E8: 2.375 | F8: 0.218 | G8: 0 | I8: A234 | J8: WPB | K8: 150 | L8: 200 | M8: 1 | N8: Ground | O8: No | P8: 45658 | Q8: Active | R8: UT | T8: 0.292 | V8: 3/8" | W8: 0.675 | X8: =IF($G$4="Default", IF(ISNUMBER(SEARCH("Straight Pipe", D8)), "A106", IF(D8="", "", "A234")), "") -> A234 | Y8: =IF($G$4="Default", IF(ISNUMBER(SEARCH("Straight Pipe", D8)), "B", IF(D8="", "", "WPB")), "") -> WPB
A9: 1.04 | B9: Bottom | C9: Piping | D9: Elbow | E9: 2.375 | F9: 0.218 | G9: 0 | I9: A234 | J9: WPB | K9: 150 | L9: 200 | M9: 1 | N9: Ground | O9: No | P9: 45658 | Q9: Active | R9: UT | T9: 0.284 | V9: 1/2" | W9: 0.84 | X9: =IF($G$4="Default", IF(ISNUMBER(SEARCH("Straight Pipe", D9)), "A106", IF(D9="", "", "A234")), "") -> A234 | Y9: =IF($G$4="Default", IF(ISNUMBER(SEARCH("Straight Pipe", D9)), "B", IF(D9="", "", "WPB")), "") -> WPB
A10: 2.01 | B10: East | C10: Piping | D10: Straight Pipe | E10: 2.375 | F10: 0.218 | G10: 0 | I10: A106 | J10: B | K10: 150 | L10: 200 | M10: 1 | N10: Ground | O10: No | P10: 45658 | Q10: Active | R10: UT | T10: 0.247 | V10: 3/4" | W10: 1.5 | X10: =IF($G$4="Default", IF(ISNUMBER(SEARCH("Straight Pipe", D10)), "A106", IF(D10="", "", "A234")), "") -> A106 | Y10: =IF($G$4="Default", IF(ISNUMBER(SEARCH("Straight Pipe", D10)), "B", IF(D10="", "", "WPB")), "") -> B
A11: 2.02 | B11: West | C11: Piping | D11: Straight Pipe | E11: 2.375 | F11: 0.218 | G11: 0 | I11: A106 | J11: B | K11: 150 | L11: 200 | M11: 1 | N11: Ground | O11: No | P11: 45658 | Q11: Active | R11: UT | T11: 0.249 | V11: 1" | W11: 1.315 | X11: =IF($G$4="Default", IF(ISNUMBER(SEARCH("Straight Pipe", D11)), "A106", IF(D11="", "", "A234")), "") -> A106 | Y11: =IF($G$4="Default", IF(ISNUMBER(SEARCH("Straight Pipe", D11)), "B", IF(D11="", "", "WPB")), "") -> B
A12: 2.03 | B12: Top | C12: Piping | D12: Straight Pipe | E12: 2.375 | F12: 0.218 | G12: 0 | I12: A106 | J12: B | K12: 150 | L12: 200 | M12: 1 | N12: Ground | O12: No | P12: 45658 | Q12: Active | R12: UT | T12: 0.257 | V12: 1.25" | W12: 1.66 | X12: =IF($G$4="Default", IF(ISNUMBER(SEARCH("Straight Pipe", D12)), "A106", IF(D12="", "", "A234")), "") -> A106 | Y12: =IF($G$4="Default", IF(ISNUMBER(SEARCH("Straight Pipe", D12)), "B", IF(D12="", "", "WPB")), "") -> B
A13: 2.04 | B13: Bottom | C13: Piping | D13: Straight Pipe | E13: 2.375 | F13: 0.218 | G13: 0 | I13: A106 | J13: B | K13: 150 | L13: 200 | M13: 1 | N13: Ground | O13: No | P13: 45658 | Q13: Active | R13: UT | T13: 0.258 | V13: 1.5" | W13: 1.9 | X13: =IF($G$4="Default", IF(ISNUMBER(SEARCH("Straight Pipe", D13)), "A106", IF(D13="", "", "A234")), "") -> A106 | Y13: =IF($G$4="Default", IF(ISNUMBER(SEARCH("Straight Pipe", D13)), "B", IF(D13="", "", "WPB")), "") -> B
A14: 3.01 | B14: North | C14: Piping | D14: Cap | E14: 1.05 | F14: 0.219 | G14: 0 | I14: A234 | J14: WPB | K14: 150 | L14: 200 | M14: 1 | N14: Ground | O14: No | P14: 45658 | Q14: Active | R14: UT | T14: 0.234 | V14: 2" | W14: 2.375 | X14: =IF($G$4="Default", IF(ISNUMBER(SEARCH("Straight Pipe", D14)), "A106", IF(D14="", "", "A234")), "") -> A234 | Y14: =IF($G$4="Default", IF(ISNUMBER(SEARCH("Straight Pipe", D14)), "B", IF(D14="", "", "WPB")), "") -> WPB
A15: 3.02 | B15: South | C15: Piping | D15: Cap | E15: 1.05 | F15: 0.219 | G15: 0 | I15: A234 | J15: WPB | K15: 150 | L15: 200 | M15: 1 | N15: Ground | O15: No | P15: 45658 | Q15: Active | R15: UT | T15: 0.234 | V15: 2.5" | W15: 2.875 | X15: =IF($G$4="Default", IF(ISNUMBER(SEARCH("Straight Pipe", D15)), "A106", IF(D15="", "", "A234")), "") -> A234 | Y15: =IF($G$4="Default", IF(ISNUMBER(SEARCH("Straight Pipe", D15)), "B", IF(D15="", "", "WPB")), "") -> WPB
A16: 3.03 | B16: Top | C16: Piping | D16: Cap | E16: 1.05 | F16: 0.219 | G16: 0 | I16: A234 | J16: WPB | K16: 150 | L16: 200 | M16: 1 | N16: Ground | O16: No | P16: 45658 | Q16: Active | R16: UT | T16: 0.241 | V16: 3" | W16: 3.5 | X16: =IF($G$4="Default", IF(ISNUMBER(SEARCH("Straight Pipe", D16)), "A106", IF(D16="", "", "A234")), "") -> A234 | Y16: =IF($G$4="Default", IF(ISNUMBER(SEARCH("Straight Pipe", D16)), "B", IF(D16="", "", "WPB")), "") -> WPB
A17: 3.04 | B17: Bottom | C17: Piping | D17: Cap | E17: 1.05 | F17: 0.219 | G17: 0 | I17: A234 | J17: WPB | K17: 150 | L17: 200 | M17: 1 | N17: Ground | O17: No | P17: 45658 | Q17: Active | R17: UT | T17: 0.242 | V17: 3.5" | W17: 4 | X17: =IF($G$4="Default", IF(ISNUMBER(SEARCH("Straight Pipe", D17)), "A106", IF(D17="", "", "A234")), "") -> A234 | Y17: =IF($G$4="Default", IF(ISNUMBER(SEARCH("Straight Pipe", D17)), "B", IF(D17="", "", "WPB")), "") -> WPB
A18: 4.01 | C18: Piping | G18: 0 | M18: 1 | Q18: Active | R18: UT | V18: 4" | W18: 4.5 | X18: =IF($G$4="Default", IF(ISNUMBER(SEARCH("Straight Pipe", D18)), "A106", IF(D18="", "", "A234")), "") | Y18: =IF($G$4="Default", IF(ISNUMBER(SEARCH("Straight Pipe", D18)), "B", IF(D18="", "", "WPB")), "")
A19: 4.02 | C19: Piping | G19: 0 | M19: 1 | Q19: Active | R19: UT | V19: 5" | W19: 5.563 | X19: =IF($G$4="Default", IF(ISNUMBER(SEARCH("Straight Pipe", D19)), "A106", IF(D19="", "", "A234")), "") | Y19: =IF($G$4="Default", IF(ISNUMBER(SEARCH("Straight Pipe", D19)), "B", IF(D19="", "", "WPB")), "")
A20: 4.03 | C20: Piping | G20: 0 | M20: 1 | Q20: Active | R20: UT | V20: 6" | W20: 6.625 | X20: =IF($G$4="Default", IF(ISNUMBER(SEARCH("Straight Pipe", D20)), "A106", IF(D20="", "", "A234")), "") | Y20: =IF($G$4="Default", IF(ISNUMBER(SEARCH("Straight Pipe", D20)), "B", IF(D20="", "", "WPB")), "")
A21: 4.04 | C21: Piping | G21: 0 | M21: 1 | Q21: Active | R21: UT | V21: 8" | W21: 8.625 | X21: =IF($G$4="Default", IF(ISNUMBER(SEARCH("Straight Pipe", D21)), "A106", IF(D21="", "", "A234")), "") | Y21: =IF($G$4="Default", IF(ISNUMBER(SEARCH("Straight Pipe", D21)), "B", IF(D21="", "", "WPB")), "")
A22: 5.01 | C22: Piping | G22: 0 | M22: 1 | Q22: Active | R22: UT | V22: 10" | W22: 10.75 | X22: =IF($G$4="Default", IF(ISNUMBER(SEARCH("Straight Pipe", D22)), "A106", IF(D22="", "", "A234")), "") | Y22: =IF($G$4="Default", IF(ISNUMBER(SEARCH("Straight Pipe", D22)), "B", IF(D22="", "", "WPB")), "")
A23: 5.02 | C23: Piping | G23: 0 | M23: 1 | Q23: Active | R23: UT | V23: 12" | W23: 12.75 | X23: =IF($G$4="Default", IF(ISNUMBER(SEARCH("Straight Pipe", D23)), "A106", IF(D23="", "", "A234")), "") | Y23: =IF($G$4="Default", IF(ISNUMBER(SEARCH("Straight Pipe", D23)), "B", IF(D23="", "", "WPB")), "")
A24: 5.03 | C24: Piping | G24: 0 | M24: 1 | Q24: Active | R24: UT | V24: 14" | W24: 14 | X24: =IF($G$4="Default", IF(ISNUMBER(SEARCH("Straight Pipe", D24)), "A106", IF(D24="", "", "A234")), "") | Y24: =IF($G$4="Default", IF(ISNUMBER(SEARCH("Straight Pipe", D24)), "B", IF(D24="", "", "WPB")), "")
A25: 5.04 | C25: Piping | G25: 0 | M25: 1 | Q25: Active | R25: UT | V25: 16" | W25: 16 | X25: =IF($G$4="Default", IF(ISNUMBER(SEARCH("Straight Pipe", D25)), "A106", IF(D25="", "", "A234")), "") | Y25: =IF($G$4="Default", IF(ISNUMBER(SEARCH("Straight Pipe", D25)), "B", IF(D25="", "", "WPB")), "")
A26: 6.01 | C26: Piping | G26: 0 | M26: 1 | Q26: Active | R26: UT | V26: 18" | W26: 18 | X26: =IF($G$4="Default", IF(ISNUMBER(SEARCH("Straight Pipe", D26)), "A106", IF(D26="", "", "A234")), "") | Y26: =IF($G$4="Default", IF(ISNUMBER(SEARCH("Straight Pipe", D26)), "B", IF(D26="", "", "WPB")), "")
A27: 6.02 | C27: Piping | G27: 0 | M27: 1 | Q27: Active | R27: UT | V27: 20" | W27: 20 | X27: =IF($G$4="Default", IF(ISNUMBER(SEARCH("Straight Pipe", D27)), "A106", IF(D27="", "", "A234")), "") | Y27: =IF($G$4="Default", IF(ISNUMBER(SEARCH("Straight Pipe", D27)), "B", IF(D27="", "", "WPB")), "")
A28: 6.03 | C28: Piping | G28: 0 | M28: 1 | Q28: Active | R28: UT | V28: 22" | W28: 22 | X28: =IF($G$4="Default", IF(ISNUMBER(SEARCH("Straight Pipe", D28)), "A106", IF(D28="", "", "A234")), "") | Y28: =IF($G$4="Default", IF(ISNUMBER(SEARCH("Straight Pipe", D28)), "B", IF(D28="", "", "WPB")), "")
A29: 6.04 | C29: Piping | G29: 0 | Q29: Active | R29: UT | V29: 24" | W29: 24 | X29: =IF($G$4="Default", IF(ISNUMBER(SEARCH("Straight Pipe", D29)), "A106", IF(D29="", "", "A234")), "") | Y29: =IF($G$4="Default", IF(ISNUMBER(SEARCH("Straight Pipe", D29)), "B", IF(D29="", "", "WPB")), "")
A30: 7.01 | C30: Piping | G30: 0 | M30: 1 | Q30: Active | R30: UT | V30: 26" | W30: 26 | X30: =IF($G$4="Default", IF(ISNUMBER(SEARCH("Straight Pipe", D30)), "A106", IF(D30="", "", "A234")), "") | Y30: =IF($G$4="Default", IF(ISNUMBER(SEARCH("Straight Pipe", D30)), "B", IF(D30="", "", "WPB")), "")
A31: 7.02 | C31: Piping | G31: 0 | M31: 1 | Q31: Active | R31: UT | V31: 28" | W31: 28 | X31: =IF($G$4="Default", IF(ISNUMBER(SEARCH("Straight Pipe", D31)), "A106", IF(D31="", "", "A234")), "") | Y31: =IF($G$4="Default", IF(ISNUMBER(SEARCH("Straight Pipe", D31)), "B", IF(D31="", "", "WPB")), "")
A32: 7.03 | C32: Piping | G32: 0 | M32: 1 | Q32: Active | R32: UT | V32: 30" | W32: 30 | X32: =IF($G$4="Default", IF(ISNUMBER(SEARCH("Straight Pipe", D32)), "A106", IF(D32="", "", "A234")), "") | Y32: =IF($G$4="Default", IF(ISNUMBER(SEARCH("Straight Pipe", D32)), "B", IF(D32="", "", "WPB")), "")
A33: 7.04 | C33: Piping | G33: 0 | M33: 1 | Q33: Active | R33: UT | V33: 32" | W33: 32 | X33: =IF($G$4="Default", IF(ISNUMBER(SEARCH("Straight Pipe", D33)), "A106", IF(D33="", "", "A234")), "") | Y33: =IF($G$4="Default", IF(ISNUMBER(SEARCH("Straight Pipe", D33)), "B", IF(D33="", "", "WPB")), "")
A34: 8.01 | C34: Piping | G34: 0 | M34: 1 | Q34: Active | R34: UT | V34: 34" | W34: 34 | X34: =IF($G$4="Default", IF(ISNUMBER(SEARCH("Straight Pipe", D34)), "A106", IF(D34="", "", "A234")), "") | Y34: =IF($G$4="Default", IF(ISNUMBER(SEARCH("Straight Pipe", D34)), "B", IF(D34="", "", "WPB")), "")
A35: 8.02 | C35: Piping | G35: 0 | M35: 1 | Q35: Active | R35: UT | V35: 36" | W35: 36 | X35: =IF($G$4="Default", IF(ISNUMBER(SEARCH("Straight Pipe", D35)), "A106", IF(D35="", "", "A234")), "") | Y35: =IF($G$4="Default", IF(ISNUMBER(SEARCH("Straight Pipe", D35)), "B", IF(D35="", "", "WPB")), "")
A36: 8.03 | C36: Piping | G36: 0 | M36: 1 | Q36: Active | R36: UT | V36: 42" | W36: 42 | X36: =IF($G$4="Default", IF(ISNUMBER(SEARCH("Straight Pipe", D36)), "A106", IF(D36="", "", "A234")), "") | Y36: =IF($G$4="Default", IF(ISNUMBER(SEARCH("Straight Pipe", D36)), "B", IF(D36="", "", "WPB")), "")
A37: 8.04 | C37: Piping | G37: 0 | M37: 1 | Q37: Active | R37: UT | X37: =IF($G$4="Default", IF(ISNUMBER(SEARCH("Straight Pipe", D37)), "A106", IF(D37="", "", "A234")), "") | Y37: =IF($G$4="Default", IF(ISNUMBER(SEARCH("Straight Pipe", D37)), "B", IF(D37="", "", "WPB")), "")
A38: 9.01 | C38: Piping | G38: 0 | M38: 1 | Q38: Active | R38: UT | X38: =IF($G$4="Default", IF(ISNUMBER(SEARCH("Straight Pipe", D38)), "A106", IF(D38="", "", "A234")), "") | Y38: =IF($G$4="Default", IF(ISNUMBER(SEARCH("Straight Pipe", D38)), "B", IF(D38="", "", "WPB")), "")
A39: 9.02 | C39: Piping | G39: 0 | M39: 1 | Q39: Active | R39: UT | X39: =IF($G$4="Default", IF(ISNUMBER(SEARCH("Straight Pipe", D39)), "A106", IF(D39="", "", "A234")), "") | Y39: =IF($G$4="Default", IF(ISNUMBER(SEARCH("Straight Pipe", D39)), "B", IF(D39="", "", "WPB")), "")
A40: 9.03 | C40: Piping | G40: 0 | M40: 1 | Q40: Active | R40: UT | X40: =IF($G$4="Default", IF(ISNUMBER(SEARCH("Straight Pipe", D40)), "A106", IF(D40="", "", "A234")), "") | Y40: =IF($G$4="Default", IF(ISNUMBER(SEARCH("Straight Pipe", D40)), "B", IF(D40="", "", "WPB")), "")
...

Sheet LWN SHEET
A1: CL 150# LWN | AB1: 1/8" | AC1: 1/4" | AD1: 3/8" | AE1: 1/2" | AF1: 3/4" | AG1: 1" | AH1: 1.25" | AI1: 1.5" | AJ1: 2" | AK1: 2.5" | AL1: 3" | AM1: 3.5" | AN1: 4" | AO1: 5" | AP1: 6" | AQ1: 8" | AR1: 10" | AS1: 12" | AT1: 14" | AU1: 16" | AV1: 18" | AW1: 20" | AX1: 22" | AY1: 24" | AZ1: 26" | BA1: 28" | BB1: 30" | BC1: 32" | BD1: 34" | BE1: 36" | BF1: 42"
B2: Barrel O.D. | I2: Neck Thickness | S2: Ellipsoidal Head | T2: Nozzle | U2: Shell | V2: Shell Tubes | AA2: ODs | AB2: 0.405 | AC2: 0.54 | AD2: 0.675 | AE2: 0.84 | AF2: 1.05 | AG2: 1.315 | AH2: 1.66 | AI2: 1.9 | AJ2: 2.375 | AK2: 2.875 | AL2: 3.5 | AM2: 4 | AN2: 4.5 | AO2: 5.563 | AP2: 6.625 | AQ2: 8.625 | AR2: 10.75 | AS2: 12.75 | AT2: 14 | AU2: 16 | AV2: 18 | AW2: 20 | AX2: 22 | AY2: 24 | AZ2: 26 | BA2: 28 | BB2: 30 | BC2: 32 | BD2: 34 | BE2: 36 | BF2: 42
A3: Size | B3: LWN | C3: HB | D3: F | E3: V 1 | F3: V 2 | G3: V 3 | H3: Size | I3: LWN | J3: HB | K3: F | L3: V 1 | M3: V 2 | N3: V 3 | S3: Top Head | T3: Nozzle 1 | U3: Shell | V3: Tube 1 | AB3: 0.049 | AC3: 0.065 | AD3: 0.065 | AE3: 0.065 | AF3: 0.065 | AG3: 0.065 | AH3: 0.065 | AI3: 0.065 | AJ3: 0.085 | AK3: 0.083 | AL3: 0.083 | AM3: 0.083 | AN3: 0.083 | AO3: 0.109 | AP3: 0.109 | AQ3: 0.109 | AR3: 0.134 | AS3: 0.156 | AT3: 0.156 | AU3: 0.165 | AV3: 0.165 | AW3: 0.188 | AX3: 0.188 | AY3: 0.218 | AZ3: 0.312 | BA3: 0.312 | BB3: 0.25 | BC3: 0.312 | BD3: 0.312 | BE3: 0.312 | BF3: 0.375
A4: ½ | B4: 1.25 | C4: 1.5 | D4: 3.5 | E4: - | F4: - | G4: - | H4: ½ | I4: 0.38 | J4: 0.48 | K4: 1.5 | L4: - | M4: - | N4: - | S4: Bottom Head | T4: Nozzle 2 | U4: Shell 1 | V4: Tube 2 | AB4: 0.068 | AC4: 0.088 | AD4: 0.091 | AE4: 0.083 | AF4: 0.83 | AG4: 0.109 | AH4: 0.109 | AI4: 0.109 | AJ4: 0.109 | AK4: 0.12 | AL4: 0.12 | AM4: 0.12 | AN4: 0.12 | AO4: 0.134 | AP4: 0.134 | AQ4: 0.148 | AR4: 0.165 | AS4: 0.188 | AT4: 0.188 | AU4: 0.25 | AV4: 0.25 | AW4: 0.25 | AX4: 0.25 | AY4: 0.25 | AZ4: 0.5 | BA4: 0.5 | BB4: 0.312 | BC4: 0.5 | BD4: 0.5 | BE4: 0.5 | BF4: 0.5
A5: ¾ | B5: 1.62 | C5: 1.88 | D5: 3.88 | E5: - | F5: - | G5: - | H5: ¾ | I5: 0.44 | J5: 0.57 | K5: 1.56 | L5: - | M5: - | N5: - | S5: North Head | T5: Nozzle 3 | U5: Shell 1 Top | V5: Tube 3 | AB5: 0.095 | AC5: 0.119 | AD5: 0.126 | AE5: 0.109 | AF5: 0.113 | AG5: 0.133 | AH5: 0.14 | AI5: 0.145 | AJ5: 0.154 | AK5: 0.203 | AL5: 0.216 | AM5: 0.226 | AN5: 0.237 | AO5: 0.258 | AP5: 0.28 | AQ5: 0.25 | AR5: 0.25 | AS5: 0.25 | AT5: 0.312 | AU5: 0.312 | AV5: 0.312 | AW5: 0.375 | AX5: 0.375 | AY5: 0.375 | AZ5: 0.375 | BA5: 0.625 | BB5: 0.5 | BC5: 0.625 | BD5: 0.625 | BE5: 0.625
A6: 1 | B6: 2 | C6: 2.25 | D6: 4.25 | E6: 2.75 | F6: 3.25 | G6: 4 | H6: 1 | I6: 0.5 | J6: 0.65 | K6: 1.62 | L6: 0.9 | M6: 1.15 | N6: 1.52 | S6: South Head | T6: Nozzle 4 | U6: Shell 1 Bot | V6: Tube 4 | AE6: 0.147 | AF6: 0.154 | AG6: 0.179 | AH6: 0.191 | AI6: 0.2 | AJ6: 0.218 | AK6: 0.276 | AL6: 0.3 | AM6: 0.318 | AN6: 0.337 | AO6: 0.375 | AP6: 0.432 | AQ6: 0.277 | AR6: 0.307 | AS6: 0.33 | AT6: 0.375 | AU6: 0.375 | AV6: 0.438 | AW6: 0.5 | AX6: 0.5 | AY6: 0.562 | BA6: 0.375 | BB6: 0.625 | BC6: 0.375 | BD6: 0.375 | BE6: 0.375
A7: 1¼ | B7: 2.38 | C7: 2.62 | D7: 4.63 | E7: - | F7: - | G7: - | H7: 1¼ | I7: 0.56 | J7: 0.67 | K7: 1.69 | L7: - | M7: - | N7: - | S7: East Head | T7: Nozzle 5 | U7: Shell 1 North | V7: Tube 5 | AE7: 0.187 | AF7: 0.219 | AG7: 0.25 | AH7: 0.25 | AI7: 0.281 | AJ7: 0.344 | AK7: 0.375 | AL7: 0.438 | AN7: 0.438 | AO7: 0.5 | AP7: 0.562 | AQ7: 0.322 | AR7: 0.365 | AS7: 0.375 | AT7: 0.438 | AU7: 0.5 | AV7: 0.375 | AW7: 0.375 | AX7: 0.875 | AY7: 0.375 | BB7: 0.375 | BC7: 0.688 | BD7: 0.688 | BE7: 0.75
A8: 1½ | B8: 2.62 | C8: 3 | D8: 5 | E8: 3.25 | F8: 4 | G8: 4.62 | H8: 1½ | I8: 0.56 | J8: 0.75 | K8: 1.75 | L8: 0.88 | M8: 1.25 | N8: 1.56 | S8: West Head | T8: Nozzle 6 | U8: Shell 1 South | V8: Tube 6 | AE8: 0.294 | AF8: 0.308 | AG8: 0.358 | AH8: 0.382 | AI8: 0.4 | AJ8: 0.436 | AK8: 0.552 | AL8: 0.6 | AN8: 0.531 | AO8: 0.625 | AP8: 0.719 | AQ8: 0.406 | AR8: 0.5 | AS8: 0.406 | AT8: 0.594 | AU8: 0.656 | AV8: 0.562 | AW8: 0.594 | AX8: 1.125 | AY8: 0.688 | BC8: 0.5 | BD8: 0.5 | BE8: 0.5
A9: 2 | B9: 3.06 | C9: 3.69 | D9: 6 | E9: 4 | F9: 4.62 | G9: 5.5 | H9: 2 | I9: 0.53 | J9: 0.88 | K9: 2 | L9: 1.03 | M9: 1.34 | N9: 1.78 | S9: Sump Head | T9: Nozzle 7 | U9: Shell 1 East | V9: Tube 7 | AN9: 0.674 | AO9: 0.75 | AP9: 0.864 | AQ9: 0.5 | AR9: 0.594 | AS9: 0.5 | AT9: 0.5 | AU9: 0.844 | AV9: 0.75 | AW9: 0.812 | AX9: 1.375 | AY9: 0.969
A10: 2½ | B10: 3.75 | C10: 4.44 | D10: 7 | E10: 4.62 | F10: 5.75 | G10: 6 | H10: 2½ | I10: 0.62 | J10: 1.06 | K10: 2.25 | L10: 1.15 | M10: 1.72 | N10: 1.84 | S10: Top Head (SS) | T10: Nozzle 8 | U10: Shell 1 West | V10: Tube 8 | AQ10: 0.594 | AR10: 0.719 | AS10: 0.562 | AT10: 0.75 | AU10: 1.031 | AV10: 0.5 | AW10: 1.31 | AX10: 1.625 | AY10: 0.5
A11: 3 | B11: 4.25 | C11: 4.94 | D11: 7.5 | E11: 5.75 | F11: 6 | G11: 6.38 | H11: 3 | I11: 0.62 | J11: 1.02 | K11: 2.25 | L11: 1.43 | M11: 1.55 | N11: 1.74 | S11: Bottom Head (SS) | T11: Nozzle 9 | U11: Shell 1 Mid | V11: Tube 9 | AQ11: 0.719 | AR11: 0.844 | AS11: 0.688 | AT11: 0.938 | AU11: 1.219 | AV11: 0.938 | AW11: 1.281 | AX11: 1.875 | AY11: 1.218
A12: 3½ | B12: 4.88 | C12: 5.94 | D12: 8.5 | E12: 6.38 | F12: 7 | G12: 7.75 | H12: 3½ | I12: 0.69 | J12: 1.29 | K12: 2.5 | L12: 1.51 | M12: 1.82 | N12: 2.2 | S12: North Head (SS) | T12: Nozzle 10 | U12: Shell 2 | V12: Tube 10 | AQ12: 0.812 | AR12: 1 | AS12: 0.844 | AT12: 1.94 | AU12: 1.438 | AV12: 1.156 | AW12: 1.5 | AX12: 2.125 | AY12: 1.531
A13: 4 | B13: 5.5 | C13: 6.44 | D13: 9 | E13: 7 | F13: 7.75 | G13: 8.25 | H13: 4 | I13: 0.75 | J13: 1.31 | K13: 2.5 | L13: 1.59 | M13: 1.96 | N13: 2.21 | S13: South Head (SS) | T13: Nozzle 11 | U13: Shell 2 Top | V13: Tube 11 | AQ13: 0.875 | AR13: 1.125 | AS13: 1 | AT13: 1.25 | AU13: 1.594 | AV13: 1.375 | AW13: 1.75 | AY13: 1.812
A14: 5 | B14: 6.5 | C14: 7.25 | D14: 10 | E14: 7.75 | F14: 8.25 | G14: 8.88 | H14: 5 | I14: 0.75 | J14: 1.22 | K14: 2.5 | L14: 1.47 | M14: 1.72 | N14: 2.04 | S14: East Head (SS) | T14: Nozzle 12 | U14: Shell 2 Bot | V14: Tube 12 | AQ14: 0.906 | AS14: 1.125 | AT14: 1.406 | AV14: 1.562 | AW14: 1.969 | AY14: 2.62
A15: 6 | B15: 7.75 | C15: 8.25 | D15: 11 | E15: 8.88 | F15: 9.88 | G15: 10.38 | H15: 6 | I15: 0.88 | J15: 1.25 | K15: 2.5 | L15: 1.56 | M15: 2.06 | N15: 2.31 | S15: West Head (SS) | T15: Nozzle 13 | U15: Shell 2 North | V15: Tube 13 | AS15: 1.312 | AV15: 1.781 | AY15: 2.344
A16: 8 | B16: 9.75 | C16: 10.5 | D16: 13.5 | E16: 11 | F16: 11.5 | G16: 12.12 | H16: 8 | I16: 0.88 | J16: 1.44 | K16: 2.75 | L16: 1.69 | M16: 1.94 | N16: 2.25 | S16: Top Head (TS) | T16: Nozzle 14 | U16: Shell 2 South | V16: Tube 14
A17: 10 | B17: 12 | C17: 12.81 | D17: 16 | E17: 13.5 | F17: 14.25 | G17: 15.12 | H17: 10 | I17: 1 | J17: 1.63 | K17: 3 | L17: 1.97 | M17: 2.35 | N17: 2.78 | S17: Bottom Head (TS) | T17: Nozzle 15 | U17: Shell 2 East | V17: Tube 15
A18: 12 | B18: 14.38 | C18: 15.56 | D18: 19 | E18: 16.25 | F18: 17.38 | G18: 18.25 | H18: 12 | I18: 1.19 | J18: 2.09 | K18: 3.5 | L18: 2.44 | M18: 3 | N18: 3.44 | S18: North Head (TS) | T18: Nozzle 16 | U18: Shell 2 West | V18: Tube 16
A19: 14 | B19: 16 | C19: 17.12 | D19: 21 | E19: 18.25 | F19: 19.38 | G19: 20.12 | H19: 14 | I19: 1 | J19: 1.56 | K19: 3.5 | L19: 2.13 | M19: 2.69 | N19: 3.06 | S19: South Head (TS) | T19: Nozzle 17 | U19: Shell 2 Mid | V19: Tube 17
A20: 16 | B20: 18 | C20: 19.62 | D20: 23.5 | E20: 20.12 | F20: 21 | G20: 22.25 | H20: 16 | I20: 1 | J20: 1.81 | K20: 3.75 | L20: 2.06 | M20: 2.5 | N20: 3.13 | S20: East Head (TS) | T20: Nozzle 18 | U20: Shell 3 | V20: Tube 18
A21: 18 | B21: 20 | C21: 20.94 | D21: 25 | E21: 22.25 | F21: 23.25 | G21: 24.12 | H21: 18 | I21: 1 | J21: 1.47 | K21: 3.5 | L21: 2.13 | M21: 2.63 | N21: 3.06 | S21: West Head (TS) | T21: Nozzle 19 | U21: Shell 3 Top | V21: Tube 19 | AQ21: 0.083
A22: 20 | B22: 22 | C22: 23.19 | D22: 27.5 | E22: 24.12 | F22: 25 | G22: 26.25 | H22: 20 | I22: 1 | J22: 1.6 | K22: 3.75 | L22: 2.06 | M22: 2.5 | N22: 3.13 | S22: Hemispherical Head | T22: Nozzle 20 | U22: Shell 3 Bot | V22: Tube 20 | AQ22: 0.109
A23: 24 | B23: 26.25 | C23: 27.5 | D23: 32 | E23: 27.75 | F23: 29.25 | G23: 30.75 | H23: 24 | I23: 1.12 | J23: 1.75 | K23: 4 | L23: 1.88 | M23: 2.63 | N23: 3.38 | S23: Top Head | T23: Nozzle 1 (SS) | U23: Shell 3 North | V23: Tube 21 | AQ23: 0.147 | BF23: 0.125 | BG23: 0.405 | BH23: 0.068 | BI23: 0.245 | BJ23: 0.095 | BK23: 0.315 | BO23: 0.125 | BP23: 0.25 | BQ23: 0.375 | BR23: 0.5 | BS23: 0.75 | BT23: 1 | BU23: 1.25 | BV23: 1.5 | BW23: 2 | BX23: 2.5 | BY23: 3 | BZ23: 3.5 | CA23: 4 | CB23: 5 | CC23: 6 | CD23: 8 | CE23: 10 | CF23: 12
A24: CL 300# LWN | S24: Bottom Head | T24: Nozzle 2 (SS) | U24: Shell 3 South | V24: Tube 22 | BF24: 0.25 | BG24: 0.54 | BH24: 0.088 | BI24: 0.425 | BJ24: 0.119 | BK24: 0.535 | BO24: 0.405 | BP24: 0.54 | BQ24: 0.675 | BR24: 0.84 | BS24: 1.05 | BT24: 1.315 | BU24: 1.66 | BV24: 1.9 | BW24: 2.375 | BX24: 2.875 | BY24: 3.5 | BZ24: 4 | CA24: 4.5 | CB24: 5.563 | CC24: 6.625 | CD24: 8.625 | CE24: 10.75 | CF24: 12.75
B25: Barrel O.D. | I25: Neck Thickness | S25: North Head | T25: Nozzle 3 (SS) | U25: Shell 3 East | V25: Tube 23 | BF25: 0.375 | BG25: 0.675 | BH25: 0.091 | BI25: 0.568 | BJ25: 0.126 | BK25: 0.739 | BO25: 0.068 | BP25: 0.088 | BQ25: 0.091 | BR25: 0.109 | BS25: 0.113 | BT25: 0.133 | BU25: 0.14 | BV25: 0.145 | BW25: 0.154 | BX25: 0.203 | BY25: 0.216 | BZ25: 0.226 | CA25: 0.237 | CB25: 0.258 | CC25: 0.28 | CD25: 0.322 | CE25: 0.365 | CF25: 0.375
A26: Size | B26: LWN | C26: HB | D26: F | E26: V 1 | F26: V 2 | G26: V 3 | H26: Size | I26: LWN | J26: HB | K26: F | L26: V 1 | M26: V 2 | N26: V 3 | S26: South Head | T26: Nozzle 4 (SS) | U26: Shell 3 West | V26: Tube 24 | BF26: 0.5 | BG26: 0.84 | BH26: 0.109 | BI26: 0.851 | BJ26: 0.147 | BK26: 1.088 | BO26: 0.245 | BP26: 0.425 | BQ26: 0.568 | BR26: 0.851 | BS26: 1.131 | BT26: 1.679 | BU26: 2.273 | BV26: 2.718 | BW26: 3.653 | BX26: 5.793 | BY26: 7.576 | BZ26: 9.109 | CA26: 10.79 | CB26: 14.62 | CC26: 18.97 | CD26: 28.55 | CE26: 40.48 | CF26: 49.56
A27: ½ | B27: 1.5 | C27: 1.75 | D27: 3.75 | E27: - | F27: - | G27: - | H27: ½ | I27: 0.5 | J27: 0.6 | K27: 1.63 | L27: - | M27: - | N27: - | S27: East Head | T27: Nozzle 5 (SS) | U27: Shell 3 Mid | V27: Tube 25 | BF27: 0.75 | BG27: 1.05 | BH27: 0.113 | BI27: 1.131 | BJ27: 0.154 | BK27: 1.474 | BO27: 0.095 | BP27: 0.119 | BQ27: 0.126 | BR27: 0.147 | BS27: 0.154 | BT27: 0.179 | BU27: 0.191 | BV27: 0.2 | BW27: 0.218 | BX27: 0.275 | BY27: 0.3 | BZ27: 0.318 | CA27: 0.337 | CB27: 0.375 | CC27: 0.432 | CD27: 0.5 | CE27: 0.5 | CF27: 0.5
A28: ¾ | B28: 1.88 | C28: 2.19 | D28: 4.62 | E28: - | F28: - | G28: - | H28: ¾ | I28: 0.57 | J28: 0.73 | K28: 1.94 | L28: - | M28: - | N28: - | S28: West Head | T28: Nozzle 6 (SS) | U28: Shell 4 | V28: Tube 26 | BF28: 1 | BG28: 1.315 | BH28: 0.133 | BI28: 1.679 | BJ28: 0.179 | BK28: 2.172 | BO28: 0.315 | BP28: 0.535 | BQ28: 0.739 | BR28: 1.088 | BS28: 1.474 | BT28: 2.172 | BU28: 2.997 | BV28: 3.631 | BW28: 5.022 | BX28: 7.661 | BY28: 10.25 | BZ28: 12.51 | CA28: 14.98 | CB28: 20.78 | CC28: 28.57 | CD28: 43.39 | CE28: 54.74 | CF28: 65.42
A29: 1 | B29: 2.12 | C29: 2.44 | D29: 4.88 | E29: 2.75 | F29: 3.75 | G29: 4 | H29: 1 | I29: 0.56 | J29: 0.74 | K29: 1.94 | L29: 0.9 | M29: 1.4 | N29: 1.52 | S29: Sump Head | T29: Nozzle 7 (SS) | U29: Shell 4 Top | V29: Tube 27 | BF29: 1.25 | BG29: 1.66 | BH29: 0.14 | BI29: 2.273 | BJ29: 0.191 | BK29: 2.997
A30: 1¼ | B30: 2.5 | C30: 2.81 | D30: 5.25 | E30: - | F30: - | G30: - | H30: 1¼ | I30: 0.63 | J30: 0.77 | K30: 2 | L30: - | M30: - | N30: - | S30: Flat Head | T30: Nozzle 8 (SS) | U30: Shell 4 Bot | V30: Tube 28 | BF30: 1.5 | BG30: 1.9 | BH30: 0.145 | BI30: 2.718 | BJ30: 0.2 | BK30: 3.631
A31: 1½ | B31: 2.75 | C31: 3.25 | D31: 6.12 | E31: 4 | F31: 4.62 | G31: 5.5 | H31: 1½ | I31: 0.63 | J31: 0.88 | K31: 2.31 | L31: 1.25 | M31: 1.56 | N31: 2 | S31: Top Head | T31: Nozzle 9 (SS) | U31: Shell 4 North | V31: Tube 29 | BF31: 2 | BG31: 2.375 | BH31: 0.154 | BI31: 3.653 | BJ31: 0.218 | BK31: 5.022
A32: 2 | B32: 3.31 | C32: 3.94 | D32: 6.5 | E32: 4.62 | F32: 5.5 | G32: 6 | H32: 2 | I32: 0.66 | J32: 1 | K32: 2.25 | L32: 1.34 | M32: 1.78 | N32: 2.03 | S32: Bottom Head | T32: Nozzle 10 (SS) | U32: Shell 4 South | V32: Tube 30 | BF32: 2.5 | BG32: 2.875 | BH32: 0.203 | BI32: 5.793 | BJ32: 0.275 | BK32: 7.661
A33: 2½ | B33: 3.94 | C33: 4.62 | D33: 7.5 | E33: 5.75 | F33: 6 | G33: 6.38 | H33: 2½ | I33: 0.72 | J33: 1.15 | K33: 2.5 | L33: 1.72 | M33: 1.84 | N33: 2.03 | S33: North Head | T33: Nozzle 11 (SS) | U33: Shell 4 East | V33: Tube 31 | BF33: 3 | BG33: 3.5 | BH33: 0.216 | BI33: 7.576 | BJ33: 0.3 | BK33: 10.25
A34: 3 | B34: 4.62 | C34: 5.38 | D34: 8.25 | E34: 6 | F34: 6.38 | G34: 7 | H34: 3 | I34: 0.81 | J34: 1.24 | K34: 2.63 | L34: 1.55 | M34: 1.74 | N34: 2.05 | S34: South Head | T34: Nozzle 12 (SS) | U34: Shell 4 West | V34: Tube 32 | BF34: 3.5 | BG34: 4 | BH34: 0.226 | BI34: 9.109 | BJ34: 0.318 | BK34: 12.51
A35: 3½ | B35: 5.25 | C35: 6 | D35: 9 | E35: 7 | F35: 7.75 | G35: 8.25 | H35: 3½ | I35: 0.88 | J35: 1.32 | K35: 2.75 | L35: 1.82 | M35: 2.2 | N35: 2.45 | S35: East Head | T35: Nozzle 13 (SS) | U35: Shell 4 Mid | V35: Tube 33 | BF35: 4 | BG35: 4.5 | BH35: 0.237 | BI35: 10.79 | BJ35: 0.337 | BK35: 14.98
A36: 4 | B36: 5.75 | C36: 6.62 | D36: 10 | E36: 7 | F36: 7.75 | G36: 8.88 | H36: 4 | I36: 0.88 | J36: 1.4 | K36: 3 | L36: 1.59 | M36: 1.96 | N36: 2.52 | S36: West Head | T36: Nozzle 14 (SS) | U36: Shell 5 | V36: Tube 34 | AA36: Straight Pipe | BF36: 5 | BG36: 5.563 | BH36: 0.258 | BI36: 14.62 | BJ36: 0.375 | BK36: 20.78
A37: 5 | B37: 7 | C37: 8 | D37: 11 | E37: 8.25 | F37: 8.88 | G37: 9.88 | H37: 5 | I37: 1 | J37: 1.6 | K37: 3 | L37: 1.72 | M37: 2.04 | N37: 2.54 | S37: Sump Head | T37: Nozzle 15 (SS) | U37: Shell 5 Top | V37: Tube 35 | AA37: Reducer | BF37: 6 | BG37: 6.625 | BH37: 0.28 | BI37: 18.97 | BJ37: 0.432 | BK37: 28.57
A38: 6 | B38: 8.12 | C38: 9.38 | D38: 12.5 | E38: 9.88 | F38: 10.38 | G38: 11 | H38: 6 | I38: 1.06 | J38: 1.81 | K38: 3.25 | L38: 2.06 | M38: 2.31 | N38: 2.62 | S38: Torispherical Head | T38: Nozzle 16 (SS) | U38: Shell 5 Bot | V38: Tube 36 | AA38: Elbow | BF38: 8 | BG38: 8.625 | BH38: 0.322 | BI38: 28.55 | BJ38: 0.5 | BK38: 43.39
A39: 8 | B39: 10.25 | C39: 11.56 | D39: 15 | E39: 12.12 | F39: 13.5 | G39: 14.25 | H39: 8 | I39: 1.13 | J39: 1.97 | K39: 3.5 | L39: 2.25 | M39: 2.94 | N39: 3.32 | S39: Top Head | T39: Nozzle 17 (SS) | U39: Shell 5 North | V39: Tube 37 | AA39: Tee | BF39: 10 | BG39: 10.75 | BH39: 0.365 | BI39: 40.48 | BJ39: 0.5 | BK39: 54.74
A40: 10 | B40: 12.62 | C40: 13.62 | D40: 17.5 | E40: 14.25 | F40: 15.12 | G40: 16.25 | H40: 10 | I40: 1.31 | J40: 2.03 | K40: 3.75 | L40: 2.35 | M40: 2.78 | N40: 3.35 | S40: Bottom Head | T40: Nozzle 18 (SS) | U40: Shell 5 South | V40: Tube 38 | AA40: Cap | BF40: 12 | BG40: 12.75 | BH40: 0.375 | BI40: 49.56 | BJ40: 0.5 | BK40: 65.42
...

Sheet Data Team Historicals
A1: Client: | B1: =IF(Vessels!$B$1<>"",Vessels!B1,Piping!B1) -> KINETIC MIDSTREAM | C1: Location: | D1: =IF(Vessels!$D$1<>"",Vessels!D1,Piping!D1) -> ARTESIA NM | F1: Facility: | G1: =IF(Vessels!$G$1<>"",Vessels!G1,Piping!G1) -> KINGS LANDING | J1: Date: | K1: =IF(Vessels!$K$1<>"",Vessels!K1,Piping!K1) -> 46072 | N1: =IF(Vessels!C2<>"","Vessels",IF(Piping!C2<>"","Piping","")) -> Piping
A2: Vessel Name: | C2: =IF(Vessels!$C$2<>"",Vessels!C2,Piping!C2) -> Amine-034 | F2: Description: | I2: =IF(Vessels!I2<>"",Vessels!I2,Piping!I2) -> F-1202 To Open Drain
A3: P&ID Page | C3: =IF(Vessels!$C$3<>"",Vessels!C3,Piping!C3) -> K1GP-PID-1201 | I3: Technician: | J3: =IF(Vessels!$J$3<>"",Vessels!J3,Piping!J3) -> Carlos Santollo
A4: Carbon or Stainless | D4: =IF(Vessels!$D$4<>"",Vessels!D4,Piping!D4) -> Carbon | G4: =IF(N1<>"Piping",Vessels!G4,"") | J4: =IF(Vessels!$J$4<>"",Vessels!J4,"")
A5: CML | B5: CML Location | C5: Component Type | D5: Component | E5: OD | F5: Nom. | G5: C.A. | H5: T-Min | I5: Mat. Spec. | J5: Mat. Grade | K5: Pressure | L5: Temp. | M5: First Insp Date | N5: First UT Reading | O5: Last Insp Date | P5: Last UT Reading | Q5: UT Reading | R5: Inspection Notes | S5: Inspected By
A6: =IF($N$1="Piping", IF(ISBLANK(Piping!A6), "", Piping!A6), IF($N$1="Vessels", IF(ISBLANK(Vessels!A6), "", Vessels!A6), "")) -> 1.01 | B6: =IF($N$1="Piping", IF(ISBLANK(Piping!B6), "", Piping!B6), IF($N$1="Vessels", IF(ISBLANK(Vessels!B6), "", Vessels!B6), "")) -> North | C6: =IF($N$1="Piping", IF(ISBLANK(Piping!C6), "", Piping!C6), IF($N$1="Vessels", IF(ISBLANK(Vessels!C6), "", Vessels!C6), "")) -> Piping | D6: =IF($N$1="Piping", IF(ISBLANK(Piping!D6), "", Piping!D6), IF($N$1="Vessels", IF(ISBLANK(Vessels!D6), "", Vessels!D6), "")) -> Elbow | E6: =IF($N$1="Piping", IF(ISBLANK(Piping!E6), "", Piping!E6), IF($N$1="Vessels", IF(ISBLANK(Vessels!E6), "", Vessels!E6), "")) -> 2.375 | F6: =IF($N$1="Piping", IF(ISBLANK(Piping!F6), "", Piping!F6), IF($N$1="Vessels", IF(ISBLANK(Vessels!F6), "", Vessels!F6), "")) -> 0.218 | G6: =IF($N$1="Piping", IF(ISBLANK(Piping!G6), "", Piping!G6), IF($N$1="Vessels", IF(ISBLANK(Vessels!G6), "", Vessels!G6), "")) -> 0 | H6: =IF($N$1="Piping", IF(ISBLANK(Piping!H6), "", Piping!H6), IF($N$1="Vessels", IF(ISBLANK(Vessels!H6), "", Vessels!H6), "")) | ... L6: =IF($N$1="Piping", IF(ISBLANK(Piping!L6), "", Piping!L6), IF($N$1="Vessels", IF(ISBLANK(Vessels!L6), "", Vessels!L6), "")) -> 200 | Q6: =IF($N$1="Piping", IF(ISBLANK(Piping!T6), "", Piping!T6), IF($N$1="Vessels", IF(ISBLANK(Vessels!T6), "", Vessels!T6), "")) -> 0.266 | R6: =IF($N$1="Piping", IF(ISBLANK(Piping!U6), "", Piping!U6), IF($N$1="Vessels", IF(ISBLANK(Vessels!U6), "", Vessels!U6), "")) | S6: =IF(B6<>"",IF($N$1="Piping", IF(ISBLANK(Piping!$J$3), "", Piping!$J$3), IF($N$1="Vessels", IF(ISBLANK(Vessels!$J$3), "", Vessels!$J$3), "")),"") -> Carlos Santollo
A7: =IF($N$1="Piping", IF(ISBLANK(Piping!A7), "", Piping!A7), IF($N$1="Vessels", IF(ISBLANK(Vessels!A7), "", Vessels!A7), "")) -> 1.02 | B7: =IF($N$1="Piping", IF(ISBLANK(Piping!B7), "", Piping!B7), IF($N$1="Vessels", IF(ISBLANK(Vessels!B7), "", Vessels!B7), "")) -> Outside Radius | C7: =IF($N$1="Piping", IF(ISBLANK(Piping!C7), "", Piping!C7), IF($N$1="Vessels", IF(ISBLANK(Vessels!C7), "", Vessels!C7), "")) -> Piping | D7: =IF($N$1="Piping", IF(ISBLANK(Piping!D7), "", Piping!D7), IF($N$1="Vessels", IF(ISBLANK(Vessels!D7), "", Vessels!D7), "")) -> Elbow | E7: =IF($N$1="Piping", IF(ISBLANK(Piping!E7), "", Piping!E7), IF($N$1="Vessels", IF(ISBLANK(Vessels!E7), "", Vessels!E7), "")) -> 2.375 | F7: =IF($N$1="Piping", IF(ISBLANK(Piping!F7), "", Piping!F7), IF($N$1="Vessels", IF(ISBLANK(Vessels!F7), "", Vessels!F7), "")) -> 0.218 | G7: =IF($N$1="Piping", IF(ISBLANK(Piping!G7), "", Piping!G7), IF($N$1="Vessels", IF(ISBLANK(Vessels!G7), "", Vessels!G7), "")) -> 0 | H7: =IF($N$1="Piping", IF(ISBLANK(Piping!H7), "", Piping!H7), IF($N$1="Vessels", IF(ISBLANK(Vessels!H7), "", Vessels!H7), "")) | ... L7: =IF($N$1="Piping", IF(ISBLANK(Piping!L7), "", Piping!L7), IF($N$1="Vessels", IF(ISBLANK(Vessels!L7), "", Vessels!L7), "")) -> 200 | Q7: =IF($N$1="Piping", IF(ISBLANK(Piping!T7), "", Piping!T7), IF($N$1="Vessels", IF(ISBLANK(Vessels!T7), "", Vessels!T7), "")) -> 0.285 | R7: =IF($N$1="Piping", IF(ISBLANK(Piping!U7), "", Piping!U7), IF($N$1="Vessels", IF(ISBLANK(Vessels!U7), "", Vessels!U7), "")) | S7: =IF(B7<>"",IF($N$1="Piping", IF(ISBLANK(Piping!$J$3), "", Piping!$J$3), IF($N$1="Vessels", IF(ISBLANK(Vessels!$J$3), "", Vessels!$J$3), "")),"") -> Carlos Santollo
A8: =IF($N$1="Piping", IF(ISBLANK(Piping!A8), "", Piping!A8), IF($N$1="Vessels", IF(ISBLANK(Vessels!A8), "", Vessels!A8), "")) -> 1.03 | B8: =IF($N$1="Piping", IF(ISBLANK(Piping!B8), "", Piping!B8), IF($N$1="Vessels", IF(ISBLANK(Vessels!B8), "", Vessels!B8), "")) -> South | C8: =IF($N$1="Piping", IF(ISBLANK(Piping!C8), "", Piping!C8), IF($N$1="Vessels", IF(ISBLANK(Vessels!C8), "", Vessels!C8), "")) -> Piping | D8: =IF($N$1="Piping", IF(ISBLANK(Piping!D8), "", Piping!D8), IF($N$1="Vessels", IF(ISBLANK(Vessels!D8), "", Vessels!D8), "")) -> Elbow | E8: =IF($N$1="Piping", IF(ISBLANK(Piping!E8), "", Piping!E8), IF($N$1="Vessels", IF(ISBLANK(Vessels!E8), "", Vessels!E8), "")) -> 2.375 | F8: =IF($N$1="Piping", IF(ISBLANK(Piping!F8), "", Piping!F8), IF($N$1="Vessels", IF(ISBLANK(Vessels!F8), "", Vessels!F8), "")) -> 0.218 | G8: =IF($N$1="Piping", IF(ISBLANK(Piping!G8), "", Piping!G8), IF($N$1="Vessels", IF(ISBLANK(Vessels!G8), "", Vessels!G8), "")) -> 0 | H8: =IF($N$1="Piping", IF(ISBLANK(Piping!H8), "", Piping!H8), IF($N$1="Vessels", IF(ISBLANK(Vessels!H8), "", Vessels!H8), "")) | ... L8: =IF($N$1="Piping", IF(ISBLANK(Piping!L8), "", Piping!L8), IF($N$1="Vessels", IF(ISBLANK(Vessels!L8), "", Vessels!L8), "")) -> 200 | Q8: =IF($N$1="Piping", IF(ISBLANK(Piping!T8), "", Piping!T8), IF($N$1="Vessels", IF(ISBLANK(Vessels!T8), "", Vessels!T8), "")) -> 0.292 | R8: =IF($N$1="Piping", IF(ISBLANK(Piping!U8), "", Piping!U8), IF($N$1="Vessels", IF(ISBLANK(Vessels!U8), "", Vessels!U8), "")) | S8: =IF(B8<>"",IF($N$1="Piping", IF(ISBLANK(Piping!$J$3), "", Piping!$J$3), IF($N$1="Vessels", IF(ISBLANK(Vessels!$J$3), "", Vessels!$J$3), "")),"") -> Carlos Santollo
A9: =IF($N$1="Piping", IF(ISBLANK(Piping!A9), "", Piping!A9), IF($N$1="Vessels", IF(ISBLANK(Vessels!A9), "", Vessels!A9), "")) -> 1.04 | B9: =IF($N$1="Piping", IF(ISBLANK(Piping!B9), "", Piping!B9), IF($N$1="Vessels", IF(ISBLANK(Vessels!B9), "", Vessels!B9), "")) -> Bottom | C9: =IF($N$1="Piping", IF(ISBLANK(Piping!C9), "", Piping!C9), IF($N$1="Vessels", IF(ISBLANK(Vessels!C9), "", Vessels!C9), "")) -> Piping | D9: =IF($N$1="Piping", IF(ISBLANK(Piping!D9), "", Piping!D9), IF($N$1="Vessels", IF(ISBLANK(Vessels!D9), "", Vessels!D9), "")) -> Elbow | E9: =IF($N$1="Piping", IF(ISBLANK(Piping!E9), "", Piping!E9), IF($N$1="Vessels", IF(ISBLANK(Vessels!E9), "", Vessels!E9), "")) -> 2.375 | F9: =IF($N$1="Piping", IF(ISBLANK(Piping!F9), "", Piping!F9), IF($N$1="Vessels", IF(ISBLANK(Vessels!F9), "", Vessels!F9), "")) -> 0.218 | G9: =IF($N$1="Piping", IF(ISBLANK(Piping!G9), "", Piping!G9), IF($N$1="Vessels", IF(ISBLANK(Vessels!G9), "", Vessels!G9), "")) -> 0 | H9: =IF($N$1="Piping", IF(ISBLANK(Piping!H9), "", Piping!H9), IF($N$1="Vessels", IF(ISBLANK(Vessels!H9), "", Vessels!H9), "")) | ... L9: =IF($N$1="Piping", IF(ISBLANK(Piping!L9), "", Piping!L9), IF($N$1="Vessels", IF(ISBLANK(Vessels!L9), "", Vessels!L9), "")) -> 200 | Q9: =IF($N$1="Piping", IF(ISBLANK(Piping!T9), "", Piping!T9), IF($N$1="Vessels", IF(ISBLANK(Vessels!T9), "", Vessels!T9), "")) -> 0.284 | R9: =IF($N$1="Piping", IF(ISBLANK(Piping!U9), "", Piping!U9), IF($N$1="Vessels", IF(ISBLANK(Vessels!U9), "", Vessels!U9), "")) | S9: =IF(B9<>"",IF($N$1="Piping", IF(ISBLANK(Piping!$J$3), "", Piping!$J$3), IF($N$1="Vessels", IF(ISBLANK(Vessels!$J$3), "", Vessels!$J$3), "")),"") -> Carlos Santollo
A10: =IF($N$1="Piping", IF(ISBLANK(Piping!A10), "", Piping!A10), IF($N$1="Vessels", IF(ISBLANK(Vessels!A10), "", Vessels!A10), "")) -> 2.01 | B10: =IF($N$1="Piping", IF(ISBLANK(Piping!B10), "", Piping!B10), IF($N$1="Vessels", IF(ISBLANK(Vessels!B10), "", Vessels!B10), "")) -> East | C10: =IF($N$1="Piping", IF(ISBLANK(Piping!C10), "", Piping!C10), IF($N$1="Vessels", IF(ISBLANK(Vessels!C10), "", Vessels!C10), "")) -> Piping | D10: =IF($N$1="Piping", IF(ISBLANK(Piping!D10), "", Piping!D10), IF($N$1="Vessels", IF(ISBLANK(Vessels!D10), "", Vessels!D10), "")) -> Straight Pipe | E10: =IF($N$1="Piping", IF(ISBLANK(Piping!E10), "", Piping!E10), IF($N$1="Vessels", IF(ISBLANK(Vessels!E10), "", Vessels!E10), "")) -> 2.375 | F10: =IF($N$1="Piping", IF(ISBLANK(Piping!F10), "", Piping!F10), IF($N$1="Vessels", IF(ISBLANK(Vessels!F10), "", Vessels!F10), "")) -> 0.218 | G10: =IF($N$1="Piping", IF(ISBLANK(Piping!G10), "", Piping!G10), IF($N$1="Vessels", IF(ISBLANK(Vessels!G10), "", Vessels!G10), "")) -> 0 | H10: =IF($N$1="Piping", IF(ISBLANK(Piping!H10), "", Piping!H10), IF($N$1="Vessels", IF(ISBLANK(Vessels!H10), "", Vessels!H10), "")) | ... L10: =IF($N$1="Piping", IF(ISBLANK(Piping!L10), "", Piping!L10), IF($N$1="Vessels", IF(ISBLANK(Vessels!L10), "", Vessels!L10), "")) -> 200 | Q10: =IF($N$1="Piping", IF(ISBLANK(Piping!T10), "", Piping!T10), IF($N$1="Vessels", IF(ISBLANK(Vessels!T10), "", Vessels!T10), "")) -> 0.247 | R10: =IF($N$1="Piping", IF(ISBLANK(Piping!U10), "", Piping!U10), IF($N$1="Vessels", IF(ISBLANK(Vessels!U10), "", Vessels!U10), "")) | S10: =IF(B10<>"",IF($N$1="Piping", IF(ISBLANK(Piping!$J$3), "", Piping!$J$3), IF($N$1="Vessels", IF(ISBLANK(Vessels!$J$3), "", Vessels!$J$3), "")),"") -> Carlos Santollo
A11: =IF($N$1="Piping", IF(ISBLANK(Piping!A11), "", Piping!A11), IF($N$1="Vessels", IF(ISBLANK(Vessels!A11), "", Vessels!A11), "")) -> 2.02 | B11: =IF($N$1="Piping", IF(ISBLANK(Piping!B11), "", Piping!B11), IF($N$1="Vessels", IF(ISBLANK(Vessels!B11), "", Vessels!B11), "")) -> West | C11: =IF($N$1="Piping", IF(ISBLANK(Piping!C11), "", Piping!C11), IF($N$1="Vessels", IF(ISBLANK(Vessels!C11), "", Vessels!C11), "")) -> Piping | D11: =IF($N$1="Piping", IF(ISBLANK(Piping!D11), "", Piping!D11), IF($N$1="Vessels", IF(ISBLANK(Vessels!D11), "", Vessels!D11), "")) -> Straight Pipe | E11: =IF($N$1="Piping", IF(ISBLANK(Piping!E11), "", Piping!E11), IF($N$1="Vessels", IF(ISBLANK(Vessels!E11), "", Vessels!E11), "")) -> 2.375 | F11: =IF($N$1="Piping", IF(ISBLANK(Piping!F11), "", Piping!F11), IF($N$1="Vessels", IF(ISBLANK(Vessels!F11), "", Vessels!F11), "")) -> 0.218 | G11: =IF($N$1="Piping", IF(ISBLANK(Piping!G11), "", Piping!G11), IF($N$1="Vessels", IF(ISBLANK(Vessels!G11), "", Vessels!G11), "")) -> 0 | H11: =IF($N$1="Piping", IF(ISBLANK(Piping!H11), "", Piping!H11), IF($N$1="Vessels", IF(ISBLANK(Vessels!H11), "", Vessels!H11), "")) | ... L11: =IF($N$1="Piping", IF(ISBLANK(Piping!L11), "", Piping!L11), IF($N$1="Vessels", IF(ISBLANK(Vessels!L11), "", Vessels!L11), "")) -> 200 | Q11: =IF($N$1="Piping", IF(ISBLANK(Piping!T11), "", Piping!T11), IF($N$1="Vessels", IF(ISBLANK(Vessels!T11), "", Vessels!T11), "")) -> 0.249 | R11: =IF($N$1="Piping", IF(ISBLANK(Piping!U11), "", Piping!U11), IF($N$1="Vessels", IF(ISBLANK(Vessels!U11), "", Vessels!U11), "")) | S11: =IF(B11<>"",IF($N$1="Piping", IF(ISBLANK(Piping!$J$3), "", Piping!$J$3), IF($N$1="Vessels", IF(ISBLANK(Vessels!$J$3), "", Vessels!$J$3), "")),"") -> Carlos Santollo
A12: =IF($N$1="Piping", IF(ISBLANK(Piping!A12), "", Piping!A12), IF($N$1="Vessels", IF(ISBLANK(Vessels!A12), "", Vessels!A12), "")) -> 2.03 | B12: =IF($N$1="Piping", IF(ISBLANK(Piping!B12), "", Piping!B12), IF($N$1="Vessels", IF(ISBLANK(Vessels!B12), "", Vessels!B12), "")) -> Top | C12: =IF($N$1="Piping", IF(ISBLANK(Piping!C12), "", Piping!C12), IF($N$1="Vessels", IF(ISBLANK(Vessels!C12), "", Vessels!C12), "")) -> Piping | D12: =IF($N$1="Piping", IF(ISBLANK(Piping!D12), "", Piping!D12), IF($N$1="Vessels", IF(ISBLANK(Vessels!D12), "", Vessels!D12), "")) -> Straight Pipe | E12: =IF($N$1="Piping", IF(ISBLANK(Piping!E12), "", Piping!E12), IF($N$1="Vessels", IF(ISBLANK(Vessels!E12), "", Vessels!E12), "")) -> 2.375 | F12: =IF($N$1="Piping", IF(ISBLANK(Piping!F12), "", Piping!F12), IF($N$1="Vessels", IF(ISBLANK(Vessels!F12), "", Vessels!F12), "")) -> 0.218 | G12: =IF($N$1="Piping", IF(ISBLANK(Piping!G12), "", Piping!G12), IF($N$1="Vessels", IF(ISBLANK(Vessels!G12), "", Vessels!G12), "")) -> 0 | H12: =IF($N$1="Piping", IF(ISBLANK(Piping!H12), "", Piping!H12), IF($N$1="Vessels", IF(ISBLANK(Vessels!H12), "", Vessels!H12), "")) | ... L12: =IF($N$1="Piping", IF(ISBLANK(Piping!L12), "", Piping!L12), IF($N$1="Vessels", IF(ISBLANK(Vessels!L12), "", Vessels!L12), "")) -> 200 | Q12: =IF($N$1="Piping", IF(ISBLANK(Piping!T12), "", Piping!T12), IF($N$1="Vessels", IF(ISBLANK(Vessels!T12), "", Vessels!T12), "")) -> 0.257 | R12: =IF($N$1="Piping", IF(ISBLANK(Piping!U12), "", Piping!U12), IF($N$1="Vessels", IF(ISBLANK(Vessels!U12), "", Vessels!U12), "")) | S12: =IF(B12<>"",IF($N$1="Piping", IF(ISBLANK(Piping!$J$3), "", Piping!$J$3), IF($N$1="Vessels", IF(ISBLANK(Vessels!$J$3), "", Vessels!$J$3), "")),"") -> Carlos Santollo
A13: =IF($N$1="Piping", IF(ISBLANK(Piping!A13), "", Piping!A13), IF($N$1="Vessels", IF(ISBLANK(Vessels!A13), "", Vessels!A13), "")) -> 2.04 | B13: =IF($N$1="Piping", IF(ISBLANK(Piping!B13), "", Piping!B13), IF($N$1="Vessels", IF(ISBLANK(Vessels!B13), "", Vessels!B13), "")) -> Bottom | C13: =IF($N$1="Piping", IF(ISBLANK(Piping!C13), "", Piping!C13), IF($N$1="Vessels", IF(ISBLANK(Vessels!C13), "", Vessels!C13), "")) -> Piping | D13: =IF($N$1="Piping", IF(ISBLANK(Piping!D13), "", Piping!D13), IF($N$1="Vessels", IF(ISBLANK(Vessels!D13), "", Vessels!D13), "")) -> Straight Pipe | E13: =IF($N$1="Piping", IF(ISBLANK(Piping!E13), "", Piping!E13), IF($N$1="Vessels", IF(ISBLANK(Vessels!E13), "", Vessels!E13), "")) -> 2.375 | F13: =IF($N$1="Piping", IF(ISBLANK(Piping!F13), "", Piping!F13), IF($N$1="Vessels", IF(ISBLANK(Vessels!F13), "", Vessels!F13), "")) -> 0.218 | G13: =IF($N$1="Piping", IF(ISBLANK(Piping!G13), "", Piping!G13), IF($N$1="Vessels", IF(ISBLANK(Vessels!G13), "", Vessels!G13), "")) -> 0 | H13: =IF($N$1="Piping", IF(ISBLANK(Piping!H13), "", Piping!H13), IF($N$1="Vessels", IF(ISBLANK(Vessels!H13), "", Vessels!H13), "")) | ... L13: =IF($N$1="Piping", IF(ISBLANK(Piping!L13), "", Piping!L13), IF($N$1="Vessels", IF(ISBLANK(Vessels!L13), "", Vessels!L13), "")) -> 200 | Q13: =IF($N$1="Piping", IF(ISBLANK(Piping!T13), "", Piping!T13), IF($N$1="Vessels", IF(ISBLANK(Vessels!T13), "", Vessels!T13), "")) -> 0.258 | R13: =IF($N$1="Piping", IF(ISBLANK(Piping!U13), "", Piping!U13), IF($N$1="Vessels", IF(ISBLANK(Vessels!U13), "", Vessels!U13), "")) | S13: =IF(B13<>"",IF($N$1="Piping", IF(ISBLANK(Piping!$J$3), "", Piping!$J$3), IF($N$1="Vessels", IF(ISBLANK(Vessels!$J$3), "", Vessels!$J$3), "")),"") -> Carlos Santollo
A14: =IF($N$1="Piping", IF(ISBLANK(Piping!A14), "", Piping!A14), IF($N$1="Vessels", IF(ISBLANK(Vessels!A14), "", Vessels!A14), "")) -> 3.01 | B14: =IF($N$1="Piping", IF(ISBLANK(Piping!B14), "", Piping!B14), IF($N$1="Vessels", IF(ISBLANK(Vessels!B14), "", Vessels!B14), "")) -> North | C14: =IF($N$1="Piping", IF(ISBLANK(Piping!C14), "", Piping!C14), IF($N$1="Vessels", IF(ISBLANK(Vessels!C14), "", Vessels!C14), "")) -> Piping | D14: =IF($N$1="Piping", IF(ISBLANK(Piping!D14), "", Piping!D14), IF($N$1="Vessels", IF(ISBLANK(Vessels!D14), "", Vessels!D14), "")) -> Cap | E14: =IF($N$1="Piping", IF(ISBLANK(Piping!E14), "", Piping!E14), IF($N$1="Vessels", IF(ISBLANK(Vessels!E14), "", Vessels!E14), "")) -> 1.05 | F14: =IF($N$1="Piping", IF(ISBLANK(Piping!F14), "", Piping!F14), IF($N$1="Vessels", IF(ISBLANK(Vessels!F14), "", Vessels!F14), "")) -> 0.219 | G14: =IF($N$1="Piping", IF(ISBLANK(Piping!G14), "", Piping!G14), IF($N$1="Vessels", IF(ISBLANK(Vessels!G14), "", Vessels!G14), "")) -> 0 | H14: =IF($N$1="Piping", IF(ISBLANK(Piping!H14), "", Piping!H14), IF($N$1="Vessels", IF(ISBLANK(Vessels!H14), "", Vessels!H14), "")) | ... L14: =IF($N$1="Piping", IF(ISBLANK(Piping!L14), "", Piping!L14), IF($N$1="Vessels", IF(ISBLANK(Vessels!L14), "", Vessels!L14), "")) -> 200 | Q14: =IF($N$1="Piping", IF(ISBLANK(Piping!T14), "", Piping!T14), IF($N$1="Vessels", IF(ISBLANK(Vessels!T14), "", Vessels!T14), "")) -> 0.234 | R14: =IF($N$1="Piping", IF(ISBLANK(Piping!U14), "", Piping!U14), IF($N$1="Vessels", IF(ISBLANK(Vessels!U14), "", Vessels!U14), "")) | S14: =IF(B14<>"",IF($N$1="Piping", IF(ISBLANK(Piping!$J$3), "", Piping!$J$3), IF($N$1="Vessels", IF(ISBLANK(Vessels!$J$3), "", Vessels!$J$3), "")),"") -> Carlos Santollo
A15: =IF($N$1="Piping", IF(ISBLANK(Piping!A15), "", Piping!A15), IF($N$1="Vessels", IF(ISBLANK(Vessels!A15), "", Vessels!A15), "")) -> 3.02 | B15: =IF($N$1="Piping", IF(ISBLANK(Piping!B15), "", Piping!B15), IF($N$1="Vessels", IF(ISBLANK(Vessels!B15), "", Vessels!B15), "")) -> South | C15: =IF($N$1="Piping", IF(ISBLANK(Piping!C15), "", Piping!C15), IF($N$1="Vessels", IF(ISBLANK(Vessels!C15), "", Vessels!C15), "")) -> Piping | D15: =IF($N$1="Piping", IF(ISBLANK(Piping!D15), "", Piping!D15), IF($N$1="Vessels", IF(ISBLANK(Vessels!D15), "", Vessels!D15), "")) -> Cap | E15: =IF($N$1="Piping", IF(ISBLANK(Piping!E15), "", Piping!E15), IF($N$1="Vessels", IF(ISBLANK(Vessels!E15), "", Vessels!E15), "")) -> 1.05 | F15: =IF($N$1="Piping", IF(ISBLANK(Piping!F15), "", Piping!F15), IF($N$1="Vessels", IF(ISBLANK(Vessels!F15), "", Vessels!F15), "")) -> 0.219 | G15: =IF($N$1="Piping", IF(ISBLANK(Piping!G15), "", Piping!G15), IF($N$1="Vessels", IF(ISBLANK(Vessels!G15), "", Vessels!G15), "")) -> 0 | H15: =IF($N$1="Piping", IF(ISBLANK(Piping!H15), "", Piping!H15), IF($N$1="Vessels", IF(ISBLANK(Vessels!H15), "", Vessels!H15), "")) | ... L15: =IF($N$1="Piping", IF(ISBLANK(Piping!L15), "", Piping!L15), IF($N$1="Vessels", IF(ISBLANK(Vessels!L15), "", Vessels!L15), "")) -> 200 | Q15: =IF($N$1="Piping", IF(ISBLANK(Piping!T15), "", Piping!T15), IF($N$1="Vessels", IF(ISBLANK(Vessels!T15), "", Vessels!T15), "")) -> 0.234 | R15: =IF($N$1="Piping", IF(ISBLANK(Piping!U15), "", Piping!U15), IF($N$1="Vessels", IF(ISBLANK(Vessels!U15), "", Vessels!U15), "")) | S15: =IF(B15<>"",IF($N$1="Piping", IF(ISBLANK(Piping!$J$3), "", Piping!$J$3), IF($N$1="Vessels", IF(ISBLANK(Vessels!$J$3), "", Vessels!$J$3), "")),"") -> Carlos Santollo
A16: =IF($N$1="Piping", IF(ISBLANK(Piping!A16), "", Piping!A16), IF($N$1="Vessels", IF(ISBLANK(Vessels!A16), "", Vessels!A16), "")) -> 3.03 | B16: =IF($N$1="Piping", IF(ISBLANK(Piping!B16), "", Piping!B16), IF($N$1="Vessels", IF(ISBLANK(Vessels!B16), "", Vessels!B16), "")) -> Top | C16: =IF($N$1="Piping", IF(ISBLANK(Piping!C16), "", Piping!C16), IF($N$1="Vessels", IF(ISBLANK(Vessels!C16), "", Vessels!C16), "")) -> Piping | D16: =IF($N$1="Piping", IF(ISBLANK(Piping!D16), "", Piping!D16), IF($N$1="Vessels", IF(ISBLANK(Vessels!D16), "", Vessels!D16), "")) -> Cap | E16: =IF($N$1="Piping", IF(ISBLANK(Piping!E16), "", Piping!E16), IF($N$1="Vessels", IF(ISBLANK(Vessels!E16), "", Vessels!E16), "")) -> 1.05 | F16: =IF($N$1="Piping", IF(ISBLANK(Piping!F16), "", Piping!F16), IF($N$1="Vessels", IF(ISBLANK(Vessels!F16), "", Vessels!F16), "")) -> 0.219 | G16: =IF($N$1="Piping", IF(ISBLANK(Piping!G16), "", Piping!G16), IF($N$1="Vessels", IF(ISBLANK(Vessels!G16), "", Vessels!G16), "")) -> 0 | H16: =IF($N$1="Piping", IF(ISBLANK(Piping!H16), "", Piping!H16), IF($N$1="Vessels", IF(ISBLANK(Vessels!H16), "", Vessels!H16), "")) | ... L16: =IF($N$1="Piping", IF(ISBLANK(Piping!L16), "", Piping!L16), IF($N$1="Vessels", IF(ISBLANK(Vessels!L16), "", Vessels!L16), "")) -> 200 | Q16: =IF($N$1="Piping", IF(ISBLANK(Piping!T16), "", Piping!T16), IF($N$1="Vessels", IF(ISBLANK(Vessels!T16), "", Vessels!T16), "")) -> 0.241 | R16: =IF($N$1="Piping", IF(ISBLANK(Piping!U16), "", Piping!U16), IF($N$1="Vessels", IF(ISBLANK(Vessels!U16), "", Vessels!U16), "")) | S16: =IF(B16<>"",IF($N$1="Piping", IF(ISBLANK(Piping!$J$3), "", Piping!$J$3), IF($N$1="Vessels", IF(ISBLANK(Vessels!$J$3), "", Vessels!$J$3), "")),"") -> Carlos Santollo
A17: =IF($N$1="Piping", IF(ISBLANK(Piping!A17), "", Piping!A17), IF($N$1="Vessels", IF(ISBLANK(Vessels!A17), "", Vessels!A17), "")) -> 3.04 | B17: =IF($N$1="Piping", IF(ISBLANK(Piping!B17), "", Piping!B17), IF($N$1="Vessels", IF(ISBLANK(Vessels!B17), "", Vessels!B17), "")) -> Bottom | C17: =IF($N$1="Piping", IF(ISBLANK(Piping!C17), "", Piping!C17), IF($N$1="Vessels", IF(ISBLANK(Vessels!C17), "", Vessels!C17), "")) -> Piping | D17: =IF($N$1="Piping", IF(ISBLANK(Piping!D17), "", Piping!D17), IF($N$1="Vessels", IF(ISBLANK(Vessels!D17), "", Vessels!D17), "")) -> Cap | E17: =IF($N$1="Piping", IF(ISBLANK(Piping!E17), "", Piping!E17), IF($N$1="Vessels", IF(ISBLANK(Vessels!E17), "", Vessels!E17), "")) -> 1.05 | F17: =IF($N$1="Piping", IF(ISBLANK(Piping!F17), "", Piping!F17), IF($N$1="Vessels", IF(ISBLANK(Vessels!F17), "", Vessels!F17), "")) -> 0.219 | G17: =IF($N$1="Piping", IF(ISBLANK(Piping!G17), "", Piping!G17), IF($N$1="Vessels", IF(ISBLANK(Vessels!G17), "", Vessels!G17), "")) -> 0 | H17: =IF($N$1="Piping", IF(ISBLANK(Piping!H17), "", Piping!H17), IF($N$1="Vessels", IF(ISBLANK(Vessels!H17), "", Vessels!H17), "")) | ... L17: =IF($N$1="Piping", IF(ISBLANK(Piping!L17), "", Piping!L17), IF($N$1="Vessels", IF(ISBLANK(Vessels!L17), "", Vessels!L17), "")) -> 200 | Q17: =IF($N$1="Piping", IF(ISBLANK(Piping!T17), "", Piping!T17), IF($N$1="Vessels", IF(ISBLANK(Vessels!T17), "", Vessels!T17), "")) -> 0.242 | R17: =IF($N$1="Piping", IF(ISBLANK(Piping!U17), "", Piping!U17), IF($N$1="Vessels", IF(ISBLANK(Vessels!U17), "", Vessels!U17), "")) | S17: =IF(B17<>"",IF($N$1="Piping", IF(ISBLANK(Piping!$J$3), "", Piping!$J$3), IF($N$1="Vessels", IF(ISBLANK(Vessels!$J$3), "", Vessels!$J$3), "")),"") -> Carlos Santollo
... A834: =IF($N$1="Piping", IF(ISBLANK(Piping!A834), "", Piping!A834), IF($N$1="Vessels", IF(ISBLANK(Vessels!A834), "", Vessels!A834), "")) -> 208.1 | B834: =IF($N$1="Piping", IF(ISBLANK(Piping!B834), "", Piping!B834), IF($N$1="Vessels", IF(ISBLANK(Vessels!B834), "", Vessels!B834), "")) | C834: =IF($N$1="Piping", IF(ISBLANK(Piping!C834), "", Piping!C834), IF($N$1="Vessels", IF(ISBLANK(Vessels!C834), "", Vessels!C834), "")) -> Piping | D834: =IF($N$1="Piping", IF(ISBLANK(Piping!D834), "", Piping!D834), IF($N$1="Vessels", IF(ISBLANK(Vessels!D834), "", Vessels!D834), "")) | E834: =IF($N$1="Piping", IF(ISBLANK(Piping!E834), "", Piping!E834), IF($N$1="Vessels", IF(ISBLANK(Vessels!E834), "", Vessels!E834), "")) | F834: =IF($N$1="Piping", IF(ISBLANK(Piping!F834), "", Piping!F834), IF($N$1="Vessels", IF(ISBLANK(Vessels!F834), "", Vessels!F834), "")) | G834: =IF($N$1="Piping", IF(ISBLANK(Piping!G834), "", Piping!G834), IF($N$1="Vessels", IF(ISBLANK(Vessels!G834), "", Vessels!G834), "")) -> 0 | H834: =IF($N$1="Piping", IF(ISBLANK(Piping!H834), "", Piping!H834), IF($N$1="Vessels", IF(ISBLANK(Vessels!H834), "", Vessels!H834), "")) | ... L834: =IF($N$1="Piping", IF(ISBLANK(Piping!L834), "", Piping!L834), IF($N$1="Vessels", IF(ISBLANK(Vessels!L834), "", Vessels!L834), "")) | Q834: =IF($N$1="Piping", IF(ISBLANK(Piping!T834), "", Piping!T834), IF($N$1="Vessels", IF(ISBLANK(Vessels!T834), "", Vessels!T834), "")) | R834: =IF($N$1="Piping", IF(ISBLANK(Piping!U834), "", Piping!U834), IF($N$1="Vessels", IF(ISBLANK(Vessels!U834), "", Vessels!U834), "")) | S834: =IF(B834<>"",IF($N$1="Piping", IF(ISBLANK(Piping!$J$3), "", Piping!$J$3), IF($N$1="Vessels", IF(ISBLANK(Vessels!$J$3), "", Vessels!$J$3), "")),"")
